<?xml version="1.0" encoding="utf-8"?>
<!-- This URDF was automatically created by SolidWorks to URDF Exporter! Originally created by Stephen Brawner (brawner@gmail.com)
     Commit Version: 1.5.1-0-g916b5db  Build Version: 1.5.7152.31018
     For more information, please see http://wiki.ros.org/sw_urdf_exporter -->
<robot
  name="tpc_mobile">
  <link name="base_footprint"/>
  <joint name = "base_joint" type="fixed">
    <parent link = "base_footprint"/>
    <child link = "base_link"/>
    <origin xyz = "0 0 0.010" rpy = "0 0 0"/>
  </joint>
  <link name="base_link">
    <inertial>
      <origin
        xyz="0.0120927150245829 0.106921966129387 -0.0501769155351696"
        rpy="0 0 0" />
      <mass
        value="74.612046426388" />
      <inertia
        ixx="5.47500132297565"
        ixy="0.0178883923983695"
        ixz="0.0574622362327499"
        iyy="7.17876390443724"
        iyz="-0.0848732174187489"
        izz="2.82590668549308" />
    </inertial>
    <visual>
      <origin
        xyz="0 0 0"
        rpy="0 0 0" />
      <geometry>
        <mesh
          filename="package://tpc_mobile_description/meshes/mobile/base_link.STL" />
      </geometry>
      <material
        name="">
        <color
          rgba="0.898039215686275 0.917647058823529 0.929411764705882 1" />
      </material>
    </visual>
    <collision>
      <origin
        xyz="0 0 0"
        rpy="0 0 0" />
      <geometry>
        <mesh
          filename="package://tpc_mobile_description/meshes/mobile/base_link.STL" />
      </geometry>
    </collision>
  </link>

  <joint name="fr_left_wheel_joint" type="continuous">
    <origin
      xyz="0.3495 -0.287 0.05"
      rpy="1.5707963267949 0 0" />
    <parent
      link="base_link" />
    <child
      link="fr_left_wheel_link" />
    <axis
      xyz="1 0 0" />
  </joint>
  <link name="fr_left_wheel_link">
    <inertial>
      <origin
        xyz="0 0 0"
        rpy="0 0 0" />
      <mass
        value="4.33590963632227" />
      <inertia
        ixx="0.0176981035324359"
        ixy="-2.94870304124652E-07"
        ixz="-4.42979461687766E-09"
        iyy="0.0112841497948592"
        iyz="-6.73288157761417E-10"
        izz="0.0112841717903316" />
    </inertial>
    <visual>
      <origin
        xyz="0 0 0"
        rpy="0 0 0" />
      <geometry>
        <mesh
          filename="package://tpc_mobile_description/meshes/mobile/fr_left_wheel_link.STL" />
      </geometry>
      <material
        name="">
        <color
          rgba="0.686274509803922 0.658823529411765 0.63921568627451 1" />
      </material>
    </visual>
    <collision>
      <origin
        xyz="0 0 0"
        rpy="0 0 0" />
      <geometry>
        <mesh
          filename="package://tpc_mobile_description/meshes/mobile/fr_left_wheel_link.STL" />
      </geometry>
    </collision>
  </link>

  <joint name="fr_right_wheel_joint" type="continuous">
    <origin
      xyz="-0.3495 -0.287 0.0500000000000001"
      rpy="1.5707963267949 0 3.14159265358979" />
    <parent
      link="base_link" />
    <child
      link="fr_right_wheel_link" />
    <axis
      xyz="-1 0 0" />
  </joint>
  <link name="fr_right_wheel_link">
    <inertial>
      <origin
        xyz="0.000555635327337989 -6.92925583321846E-07 1.74224749110996E-06"
        rpy="0 0 0" />
      <mass
        value="6.17811527090236" />
      <inertia
        ixx="0.0269359902916775"
        ixy="-3.07055496963113E-07"
        ixz="6.57121411481947E-09"
        iyy="0.0173277806795012"
        iyz="-1.48194959304277E-10"
        izz="0.0173278258813899" />
    </inertial>
    <visual>
      <origin
        xyz="0 0 0"
        rpy="0 0 0" />
      <geometry>
        <mesh
          filename="package://tpc_mobile_description/meshes/mobile/fr_right_wheel_link.STL" />
      </geometry>
      <material
        name="">
        <color
          rgba="0.686274509803922 0.658823529411765 0.63921568627451 1" />
      </material>
    </visual>
    <collision>
      <origin
        xyz="0 0 0"
        rpy="0 0 0" />
      <geometry>
        <mesh
          filename="package://tpc_mobile_description/meshes/mobile/fr_right_wheel_link.STL" />
      </geometry>
    </collision>
  </link>

  <joint name="rr_left_wheel_joint" type="continuous">
    <origin
      xyz="0.3495 0.287 0.05"
      rpy="1.5707963267949 0 0" />
    <parent
      link="base_link" />
    <child
      link="rr_left_wheel_link" />
    <axis
      xyz="1 0 0" />
  </joint>
  <link name="rr_left_wheel_link">
    <inertial>
      <origin
        xyz="0.000555636107377688 -6.92709553738735E-07 1.74278912390413E-06"
        rpy="0 0 0" />
      <mass
        value="6.17811533675191" />
      <inertia
        ixx="0.0269359905011406"
        ixy="-3.06946707282074E-07"
        ixz="6.43701516295571E-09"
        iyy="0.0173277810497043"
        iyz="-1.21551298052357E-10"
        izz="0.0173278258317422" />
    </inertial>
    <visual>
      <origin
        xyz="0 0 0"
        rpy="0 0 0" />
      <geometry>
        <mesh
          filename="package://tpc_mobile_description/meshes/mobile/rr_left_wheel_link.STL" />
      </geometry>
      <material
        name="">
        <color
          rgba="0.686274509803922 0.658823529411765 0.63921568627451 1" />
      </material>
    </visual>
    <collision>
      <origin
        xyz="0 0 0"
        rpy="0 0 0" />
      <geometry>
        <mesh
          filename="package://tpc_mobile_description/meshes/mobile/rr_left_wheel_link.STL" />
      </geometry>
    </collision>
  </link>

  <joint name="rr_right_wheel_joint" type="continuous">
    <origin
      xyz="-0.3495 0.287 0.05"
      rpy="1.5707963267949 0 3.14159265358979" />
    <parent
      link="base_link" />
    <child
      link="rr_right_wheel_link" />
    <axis
      xyz="-1 0 0" />
  </joint>
  <link name="rr_right_wheel_link">
    <inertial>
      <origin
        xyz="0.000346711534812749 -9.55608986691336E-07 1.77275715773639E-08"
        rpy="0 0 0" />
      <mass
        value="4.33590963632227" />
      <inertia
        ixx="0.0176981035324359"
        ixy="-2.94870304133278E-07"
        ixz="-4.42979462853889E-09"
        iyy="0.0112841497948592"
        iyz="-6.73288160750513E-10"
        izz="0.0112841717903316" />
    </inertial>
    <visual>
      <origin
        xyz="0 0 0"
        rpy="0 0 0" />
      <geometry>
        <mesh
          filename="package://tpc_mobile_description/meshes/mobile/rr_right_wheel_link.STL" />
      </geometry>
      <material
        name="">
        <color
          rgba="0.686274509803922 0.658823529411765 0.63921568627451 1" />
      </material>
    </visual>
    <collision>
      <origin
        xyz="0 0 0"
        rpy="0 0 0" />
      <geometry>
        <mesh
          filename="package://tpc_mobile_description/meshes/mobile/rr_right_wheel_link.STL" />
      </geometry>
    </collision>
  </link>

  <joint name="imu_joint" type="fixed">
    <origin
      xyz="0 0 0"
      rpy="0 0 -3.14159265358979" />
    <parent
      link="base_link" />
    <child
      link="imu_link" />
    <axis
      xyz="0 0 0" />
  </joint>
  <link name="imu_link">
    <inertial>
      <origin
        xyz="-2.30441111959726E-08 -6.16283038051961E-07 0.019948798622652"
        rpy="0 0 0" />
      <mass
        value="0.0117804617116584" />
      <inertia
        ixx="1.24424778618368E-06"
        ixy="1.92239989053571E-12"
        ixz="1.36019571723451E-12"
        iyy="1.24427423107387E-06"
        iyz="3.63163770754019E-11"
        izz="2.29188401372467E-06" />
    </inertial>
    <visual>
      <origin
        xyz="0 0 0"
        rpy="0 0 0" />
      <geometry>
        <mesh
          filename="package://tpc_mobile_description/meshes/mobile/imu_link.STL" />
      </geometry>
      <material
        name="">
        <color
          rgba="0.631372549019608 0.588235294117647 0.509803921568627 1" />
      </material>
    </visual>
    <collision>
      <origin
        xyz="0 0 0"
        rpy="0 0 0" />
      <geometry>
        <mesh
          filename="package://tpc_mobile_description/meshes/mobile/imu_link.STL" />
      </geometry>
    </collision>
  </link>

  <joint
    name="lidar_joint"
    type="fixed">
    <!--<origin
      xyz="-0.0128411617909521 -0.401095076137313 0.247303963631305"
      rpy="1.5707963267949 0 -1.56143748001795" />-->
    <origin
        xyz="0 -0.33 0.26"
        rpy="0 0 -1.5707963267949" />
    <parent
      link="base_link" />
    <child
      link="lidar_link" />
    <axis
      xyz="0 0 0" />
  </joint>
  <link
    name="lidar_link">
    <inertial>
      <origin
        xyz="-0.423900964027476 -0.128670344187783 -0.0173074417735623"
        rpy="0 0 0" />
      <mass
        value="104.627670689358" />
      <inertia
        ixx="7.02508200066988"
        ixy="-1.30027634117536"
        ixz="-0.6108584226253"
        iyy="13.0892399888305"
        iyz="-0.253008067332665"
        izz="10.1215957977667" />
    </inertial>
    <visual>
      <origin
          xyz="0 0 0"
          rpy="-1.5707963267949 0 0" />
      <!--<origin
        xyz="0 0 0"
        rpy="0 0 0" />-->
      <geometry>
        <mesh
          filename="package://tpc_mobile_description/meshes/mobile/lidar_link.STL" />
      </geometry>
      <material
        name="">
        <color
          rgba="0.792156862745098 0.819607843137255 0.933333333333333 1" />
      </material>
    </visual>
    <collision>
      <origin
        xyz="0 0 0"
        rpy="0 0 0" />
      <geometry>
        <mesh
          filename="package://tpc_mobile_description/meshes/mobile/lidar_link.STL" />
      </geometry>
    </collision>
  </link>

</robot>
